<?xml version="1.0" encoding="utf-8"?>
<!-- =================================================================================== -->
<!-- |    This document was autogenerated by xacro from /home/antonis/Documents/GitHub/penelope_ws/src/COMAU_ROS/comau_experimental_ws/comau_description/aura_description/robots/aura_robot.urdf.xacro | -->
<!-- |    EDITING THIS FILE BY HAND IS NOT RECOMMENDED                                 | -->
<!-- =================================================================================== -->
<robot name="aura">
  <!-- 
    Author: LMS
   -->
  <gazebo>
    <plugin filename="libgazebo_ros_control.so" name="ros_control">
      <controlPeriod>0.001</controlPeriod>
    </plugin>
  </gazebo>
  <transmission name="joint_1_trans">
    <type>transmission_interface/SimpleTransmission</type>
    <joint name="joint_1">
      <hardwareInterface>hardware_interface/PositionJointInterface</hardwareInterface>
    </joint>
    <actuator name="joint_1_motor">
      <mechanicalReduction>1</mechanicalReduction>
    </actuator>
  </transmission>
  <transmission name="joint_2_trans">
    <type>transmission_interface/SimpleTransmission</type>
    <joint name="joint_2">
      <hardwareInterface>hardware_interface/PositionJointInterface</hardwareInterface>
    </joint>
    <actuator name="joint_2_motor">
      <mechanicalReduction>1</mechanicalReduction>
    </actuator>
  </transmission>
  <transmission name="joint_3_trans">
    <type>transmission_interface/SimpleTransmission</type>
    <joint name="joint_3">
      <hardwareInterface>hardware_interface/PositionJointInterface</hardwareInterface>
    </joint>
    <actuator name="joint_3_motor">
      <mechanicalReduction>1</mechanicalReduction>
    </actuator>
  </transmission>
  <transmission name="joint_4_trans">
    <type>transmission_interface/SimpleTransmission</type>
    <joint name="joint_4">
      <hardwareInterface>hardware_interface/PositionJointInterface</hardwareInterface>
    </joint>
    <actuator name="joint_4_motor">
      <mechanicalReduction>1</mechanicalReduction>
    </actuator>
  </transmission>
  <transmission name="joint_5_trans">
    <type>transmission_interface/SimpleTransmission</type>
    <joint name="joint_5">
      <hardwareInterface>hardware_interface/PositionJointInterface</hardwareInterface>
    </joint>
    <actuator name="joint_5_motor">
      <mechanicalReduction>1</mechanicalReduction>
    </actuator>
  </transmission>
  <transmission name="joint_6_trans">
    <type>transmission_interface/SimpleTransmission</type>
    <joint name="joint_6">
      <hardwareInterface>hardware_interface/PositionJointInterface</hardwareInterface>
    </joint>
    <actuator name="joint_6_motor">
      <mechanicalReduction>1</mechanicalReduction>
    </actuator>
  </transmission>
  <!--gazebo reference="${prefix}aura_footprint">
      <static>true</static>
    </gazebo-->
  <gazebo reference="base_link">
    <static>true</static>
    <gravity>false</gravity>
    <selfCollide>false</selfCollide>
    <material>Gazebo/DarkGrey</material>
  </gazebo>
  <gazebo reference="link_1">
    <gravity>false</gravity>
    <selfCollide>false</selfCollide>
    <material>Gazebo/Blue</material>
  </gazebo>
  <gazebo reference="link_2">
    <gravity>false</gravity>
    <selfCollide>false</selfCollide>
    <material>Gazebo/Grey</material>
  </gazebo>
  <gazebo reference="link_3">
    <gravity>false</gravity>
    <selfCollide>false</selfCollide>
    <material>Gazebo/Grey</material>
  </gazebo>
  <gazebo reference="link_3_virtual">
    <gravity>false</gravity>
    <selfCollide>false</selfCollide>
    <material>Gazebo/Grey</material>
  </gazebo>
  <gazebo reference="link_4">
    <gravity>false</gravity>
    <selfCollide>false</selfCollide>
    <material>Gazebo/Grey</material>
  </gazebo>
  <gazebo reference="link_5">
    <gravity>false</gravity>
    <selfCollide>false</selfCollide>
    <material>Gazebo/Blue</material>
  </gazebo>
  <gazebo reference="link_6">
    <gravity>false</gravity>
    <selfCollide>false</selfCollide>
    <material>Gazebo/Black</material>
  </gazebo>
  <link name="base_link">
    <inertial>
      <origin rpy="0 0 0" xyz="0.0190768727000594 -0.00273219739469353 0.224558520234347"/>
      <mass value="6.1430439187"/>
      <inertia ixx="28.5802635516256" ixy="0.00727927797804216" ixz="0.299680358784856" iyy="31.073773310292" iyz="0.0069437441373793" izz="56.3330921844227"/>
    </inertial>
    <visual>
      <origin rpy="0 0 0" xyz="0 0 0"/>
      <geometry>
        <mesh filename="package://aura_description/meshes/aura/viz/base_link.STL"/>
      </geometry>
      <material name="comau_dark_grey">
        <color rgba="0.25098 0.25098 0.25098 1"/>
      </material>
    </visual>
    <collision>
      <surface>
        <contact>
          <collide_bitmask>0x01</collide_bitmask>
        </contact>
      </surface>
      <origin rpy="0 0 0" xyz="0 0 0"/>
      <geometry>
        <mesh filename="package://aura_description/meshes/aura/col/base_link.STL"/>
      </geometry>
    </collision>
  </link>
  <link name="link_1">
    <inertial>
      <origin rpy="0 0 0" xyz="0.266373725873378 0.00385598734773701 0.381638394835449"/>
      <mass value="8.48522894702"/>
      <inertia ixx="49.3087902451513" ixy="0.86766706218942" ixz="-11.6355039302912" iyy="47.6784496847126" iyz="0.356500383449339" izz="50.5565394772442"/>
    </inertial>
    <visual>
      <origin rpy="0 0 0" xyz="0 0 0"/>
      <geometry>
        <mesh filename="package://aura_description/meshes/aura/viz/Axis-1.STL"/>
      </geometry>
      <material name="comau_blue">
        <color rgba="0 0 1 1"/>
      </material>
    </visual>
    <collision>
      <origin rpy="0 0 0" xyz="0 0 0"/>
      <surface>
        <contact>
          <collide_bitmask>0x10</collide_bitmask>
        </contact>
      </surface>
      <geometry>
        <mesh filename="package://aura_description/meshes/aura/col/Axis-1.STL"/>
      </geometry>
    </collision>
  </link>
  <link name="link_2">
    <inertial>
      <origin rpy="0 0 0" xyz="-0.130676544255706 -0.0799633110698596 0.420177344523501"/>
      <mass value="2.39125682402"/>
      <inertia ixx="29.0000847886552" ixy="-0.0137913581559178" ixz="-0.38050514193246" iyy="29.5862783708273" iyz="0.448920656507232" izz="3.35361301596861"/>
    </inertial>
    <visual>
      <origin rpy="0 0 0" xyz="0 0 0"/>
      <geometry>
        <mesh filename="package://aura_description/meshes/aura/viz/Axis-2.STL"/>
      </geometry>
      <material name="comau_grey">
        <color rgba="0.752941176470588 0.752941176470588 0.752941176470588 1"/>
      </material>
    </visual>
    <collision>
      <origin rpy="0 0 0" xyz="0 0 0"/>
      <surface>
        <contact>
          <collide_bitmask>0x01</collide_bitmask>
        </contact>
      </surface>
      <geometry>
        <mesh filename="package://aura_description/meshes/aura/col/Axis-2.STL"/>
      </geometry>
    </collision>
  </link>
  <link name="link_3">
    <inertial>
      <origin rpy="0 0 0" xyz="-0.0729518648260472 0.0292430153422261 0.190940156994843"/>
      <mass value="3.11238256143"/>
      <inertia ixx="11.54793486791" ixy="0.0389853984707502" ixz="-0.961629773567723" iyy="8.37635262458699" iyz="-0.92294880100034" izz="9.81126840885521"/>
    </inertial>
    <visual>
      <origin rpy="0 0 0" xyz="0 0 0"/>
      <geometry>
        <mesh filename="package://aura_description/meshes/aura/viz/Axis-3.STL"/>
      </geometry>
      <material name="comau_grey">
        <color rgba="0.752941176470588 0.752941176470588 0.752941176470588 1"/>
      </material>
    </visual>
    <collision>
      <origin rpy="0 0 0" xyz="0 0 0"/>
      <surface>
        <contact>
          <collide_bitmask>0x01</collide_bitmask>
        </contact>
      </surface>
      <geometry>
        <mesh filename="package://aura_description/meshes/aura/col/Axis-3.STL"/>
      </geometry>
    </collision>
  </link>
  <link name="link_3_virtual">
    <inertial>
      <origin rpy="0 0 0" xyz="0 0 0"/>
      <mass value="0.001"/>
      <inertia ixx="0.0001" ixy="0" ixz="0" iyy="0.0001" iyz="0" izz="0.0001"/>
    </inertial>
  </link>
  <link name="link_4">
    <inertial>
      <origin rpy="0 0 0" xyz="0.812887178114926 0.000362663375719755 -0.00614579685957262"/>
      <mass value="1.36485755345"/>
      <inertia ixx="1.44924828438087" ixy="-0.0010420322322568" ixz="0.182154802830561" iyy="23.7605547929294" iyz="0.0398572873015" izz="23.7018207836833"/>
    </inertial>
    <visual>
      <origin rpy="0 0 0" xyz="0 0 0"/>
      <geometry>
        <mesh filename="package://aura_description/meshes/aura/viz/Axis-4.STL"/>
      </geometry>
      <material name="comau_grey">
        <color rgba="0.752941176470588 0.752941176470588 0.752941176470588 1"/>
      </material>
    </visual>
    <collision>
      <origin rpy="0 0 0" xyz="0 0 0"/>
      <surface>
        <contact>
          <collide_bitmask>0x01</collide_bitmask>
        </contact>
      </surface>
      <geometry>
        <mesh filename="package://aura_description/meshes/aura/col/Axis-4.STL"/>
      </geometry>
    </collision>
  </link>
  <link name="link_5">
    <inertial>
      <origin rpy="0 0 0" xyz="0.0568185601062883 0.000539823436256374 0.13348534058869"/>
      <mass value="0.386467341461"/>
      <inertia ixx="0.470449491695078" ixy="-0.000517824470923669" ixz="0.0313276463840993" iyy="0.615934928772394" iyz="-0.000786523511302322" izz="0.418403890019268"/>
    </inertial>
    <visual>
      <origin rpy="0 0 0" xyz="0 0 0"/>
      <geometry>
        <mesh filename="package://aura_description/meshes/aura/viz/Axis-5.STL"/>
      </geometry>
      <material name="comau_blue">
        <color rgba="0 0 1 1"/>
      </material>
    </visual>
    <collision>
      <origin rpy="0 0 0" xyz="0 0 0"/>
      <surface>
        <contact>
          <collide_bitmask>0x10</collide_bitmask>
        </contact>
      </surface>
      <geometry>
        <mesh filename="package://aura_description/meshes/aura/col/Axis-5.STL"/>
      </geometry>
    </collision>
  </link>
  <link name="link_6">
    <inertial>
      <origin rpy="0 0 0" xyz="0.0242228852262389 0.00139203375363176 0.000729669966204494"/>
      <mass value="0.0792214111422"/>
      <inertia ixx="0.0703548868386956" ixy="0.000116981956754875" ixz="9.17709285092661E-05" iyy="0.0355404313512897" iyz="-0.000841076901867076" izz="0.0361480651851593"/>
    </inertial>
    <visual>
      <origin rpy="0 0 0" xyz="0 0 0"/>
      <geometry>
        <mesh filename="package://aura_description/meshes/aura/viz/Axis-6.STL"/>
      </geometry>
      <material name="comau_dark_grey">
        <color rgba="0.25098 0.25098 0.25098 1"/>
      </material>
    </visual>
    <collision>
      <origin rpy="0 0 0" xyz="0 0 0"/>
      <surface>
        <contact>
          <collide_bitmask>0x01</collide_bitmask>
        </contact>
      </surface>
      <geometry>
        <mesh filename="package://aura_description/meshes/aura/col/Axis-6.STL"/>
      </geometry>
    </collision>
  </link>
  <link name="ee_link"/>
  <!-- joints: main serial chain -->
  <joint name="joint_1" type="revolute">
    <origin rpy="0 0 0" xyz="0 0 0.466"/>
    <parent link="base_link"/>
    <child link="link_1"/>
    <axis xyz="0 0 -1"/>
    <limit effort="6300.0" lower="-3.14" upper="3.14" velocity="2.0"/>
    <dynamics damping="0.02" friction="0.0"/>
  </joint>
  <joint name="joint_2" type="revolute">
    <origin rpy="0 0 0" xyz="0.4 0 0.504"/>
    <parent link="link_1"/>
    <child link="link_2"/>
    <axis xyz="0 1 0"/>
    <limit effort="3300.0" lower="-0.34" upper="1.48" velocity="2.0"/>
    <dynamics damping="0.02" friction="0.0"/>
  </joint>
  <joint name="joint_2m" type="fixed">
    <origin rpy="0 -1.57079632679 0" xyz="0 0 1.175"/>
    <parent link="link_2"/>
    <child link="link_3_virtual"/>
  </joint>
  <joint name="joint_3" type="revolute">
    <origin rpy="0 0 0" xyz="0 0 0"/>
    <parent link="link_3_virtual"/>
    <child link="link_3"/>
    <axis xyz="0 -1 0"/>
    <!--0.34, 0.88 upper lower -0.69-->
    <!--0.69 0.88 -->
    <limit effort="1000.0" lower="-2.2607" upper="-0.69079" velocity="2.0"/>
    <dynamics damping="0.02" friction="0.0"/>
  </joint>
  <joint name="joint_4" type="revolute">
    <origin rpy="0 0 0" xyz="0.105 0 0.249999999999999"/>
    <parent link="link_3"/>
    <child link="link_4"/>
    <axis xyz="-1 0 0"/>
    <limit effort="60.0" lower="-3.14" upper="3.14" velocity="2.0"/>
    <dynamics damping="0.02" friction="0.0"/>
  </joint>
  <joint name="joint_5" type="revolute">
    <origin rpy="0 0 0" xyz="1.279 0 0.029358"/>
    <parent link="link_4"/>
    <child link="link_5"/>
    <axis xyz="0.5 0 0.86603"/>
    <limit effort="60.0" lower="-3.14" upper="3.14" velocity="2.0"/>
    <dynamics damping="0.02" friction="0.0"/>
  </joint>
  <joint name="joint_6" type="revolute">
    <origin rpy="0 0 0" xyz="0.16105 0 0.10055"/>
    <parent link="link_5"/>
    <child link="link_6"/>
    <axis xyz="-1 0 0"/>
    <limit effort="60.0" lower="-3.49" upper="3.49" velocity="2.0"/>
    <dynamics damping="0.02" friction="0.0"/>
  </joint>
  <joint name="fixed_ee_joint" type="fixed">
    <origin rpy="0 0 0" xyz="0.0 0 0.0"/>
    <parent link="link_6"/>
    <child link="ee_link"/>
  </joint>
  <link name="world"/>
  <joint name="world_joint" type="fixed">
    <parent link="world"/>
    <child link="base_link"/>
    <origin rpy="0 0 0" xyz="0 0 0"/>
  </joint>
</robot>

